<?xml version="1.0" encoding="UTF-8"?><testsuite name="nosetests" tests="10" errors="2" failures="0" skip="0"><testcase classname="tests.test_api.TestApi" name="test_get_info" time="0.001"></testcase><testcase classname="tests.test_api.TestApi" name="test_init_api" time="0.000"></testcase><testcase classname="tests.test_api.TestApi" name="test_run" time="0.001"></testcase><testcase classname="tests.test_nose_adapter.TestNoseAdapters" name="test_get_nose_transport" time="0.000"></testcase><testcase classname="tests.test_sql_storage.SqlStorageTests" name="test_add_test_result" time="0.007"></testcase><testcase classname="tests.test_sql_storage.SqlStorageTests" name="test_add_test_run" time="0.003"></testcase><testcase classname="tests.test_sql_storage.SqlStorageTests" name="test_create_session" time="0.003"></testcase><testcase classname="tests.test_sql_storage.SqlStorageTests" name="test_get_test_results" time="0.006"></testcase><testcase classname="tests.test_v1_rest_api.ApiV1Tests" name="test_get_call" time="0.002"><error type="exceptions.SystemExit" message="2"><![CDATA[Traceback (most recent call last):
  File "/home/dshulyak/.virtualenvs/testing-adapter/local/lib/python2.7/site-packages/nose/case.py", line 133, in run
    self.runTest(result)
  File "/home/dshulyak/.virtualenvs/testing-adapter/local/lib/python2.7/site-packages/nose/case.py", line 151, in runTest
    test(result)
  File "/home/dshulyak/.virtualenvs/testing-adapter/local/lib/python2.7/site-packages/unittest2/case.py", line 398, in __call__
    return self.run(*args, **kwds)
  File "/home/dshulyak/.virtualenvs/testing-adapter/local/lib/python2.7/site-packages/unittest2/case.py", line 333, in run
    self.setUp()
  File "/home/dshulyak/projects/testing-adapter/tests/test_v1_rest_api.py", line 11, in setUp
    self.app = TestApp(app.setup_app())
  File "/home/dshulyak/projects/testing-adapter/core/wsgi/app.py", line 14, in setup_app
    cfg.CONF(project='testing_adapter', default_config_files=[])
  File "/home/dshulyak/.virtualenvs/testing-adapter/local/lib/python2.7/site-packages/oslo/config/cfg.py", line 1174, in __call__
    else sys.argv[1:])
  File "/home/dshulyak/.virtualenvs/testing-adapter/local/lib/python2.7/site-packages/oslo/config/cfg.py", line 1684, in _parse_cli_opts
    return vars(self._oparser.parse_args(args))
  File "/usr/lib/python2.7/argparse.py", line 1691, in parse_args
    self.error(msg % ' '.join(argv))
  File "/usr/lib/python2.7/argparse.py", line 2347, in error
    self.exit(2, _('%s: error: %s\n') % (self.prog, message))
  File "/usr/lib/python2.7/argparse.py", line 2335, in exit
    _sys.exit(status)
SystemExit: 2
]]></error><system-err><![CDATA[usage: nosetests [-h] [--version] [--config-file PATH] [--config-dir DIR]
nosetests: error: unrecognized arguments: --with-xunit
]]></system-err></testcase><testcase classname="tests.test_v1_rest_api.ApiV1Tests" name="test_post_call" time="0.002"><error type="exceptions.SystemExit" message="2"><![CDATA[Traceback (most recent call last):
  File "/home/dshulyak/.virtualenvs/testing-adapter/local/lib/python2.7/site-packages/nose/case.py", line 133, in run
    self.runTest(result)
  File "/home/dshulyak/.virtualenvs/testing-adapter/local/lib/python2.7/site-packages/nose/case.py", line 151, in runTest
    test(result)
  File "/home/dshulyak/.virtualenvs/testing-adapter/local/lib/python2.7/site-packages/unittest2/case.py", line 398, in __call__
    return self.run(*args, **kwds)
  File "/home/dshulyak/.virtualenvs/testing-adapter/local/lib/python2.7/site-packages/unittest2/case.py", line 333, in run
    self.setUp()
  File "/home/dshulyak/projects/testing-adapter/tests/test_v1_rest_api.py", line 11, in setUp
    self.app = TestApp(app.setup_app())
  File "/home/dshulyak/projects/testing-adapter/core/wsgi/app.py", line 14, in setup_app
    cfg.CONF(project='testing_adapter', default_config_files=[])
  File "/home/dshulyak/.virtualenvs/testing-adapter/local/lib/python2.7/site-packages/oslo/config/cfg.py", line 1174, in __call__
    else sys.argv[1:])
  File "/home/dshulyak/.virtualenvs/testing-adapter/local/lib/python2.7/site-packages/oslo/config/cfg.py", line 1684, in _parse_cli_opts
    return vars(self._oparser.parse_args(args))
  File "/usr/lib/python2.7/argparse.py", line 1691, in parse_args
    self.error(msg % ' '.join(argv))
  File "/usr/lib/python2.7/argparse.py", line 2347, in error
    self.exit(2, _('%s: error: %s\n') % (self.prog, message))
  File "/usr/lib/python2.7/argparse.py", line 2335, in exit
    _sys.exit(status)
SystemExit: 2
]]></error><system-err><![CDATA[usage: nosetests [-h] [--version] [--config-file PATH] [--config-dir DIR]
nosetests: error: unrecognized arguments: --with-xunit
]]></system-err></testcase></testsuite>